Workbook

Sheet Wikidata_upec_chemical_20
A1: docid | B1: title | C1: keyword | D1: wikidata_label | E1: wikidata_qid | F1: bnf_id | G1: p279_path | H1: retry_source | I1: match_stage | J1: is_disambiguation | K1: label_similarity | L1: match_score | M1: p31_types | N1: p31_label | O1: Check
A2: 1006198 | B2: Harmonic mechanical excitations of steady convective instabilities: a means to get more uniform heat transfers in mixed convection flows? | C2: Mixed convection | H2: none | I2: none | J2: no | K2: 0 | L2: 0 | O2: ok
A3: 1006198 | B3: Harmonic mechanical excitations of steady convective instabilities: a means to get more uniform heat transfers in mixed convection flows? | C3: Poiseuille-Rayleigh-BÃ©nard flow | H3: none | I3: none | J3: no | K3: 0 | L3: 0 | O3: ok
A4: 1006198 | B4: Harmonic mechanical excitations of steady convective instabilities: a means to get more uniform heat transfers in mixed convection flows? | C4: Convective instability | D4: Convective instability | E4: Q3268911 | G4: instability > risk source > source > entity | H4: context | I4: context | J4: no | K4: 100 | L4: 111 | O4: ok
A5: 1006198 | B5: Harmonic mechanical excitations of steady convective instabilities: a means to get more uniform heat transfers in mixed convection flows? | C5: Convective instability | D5: Convective instability | E5: Q3268911 | G5: instability > state > phenomenon > occurrent > entity | H5: context | I5: context | J5: no | K5: 100 | L5: 111 | O5: ok
A6: 1006198 | B6: Harmonic mechanical excitations of steady convective instabilities: a means to get more uniform heat transfers in mixed convection flows? | C6: Convective instability | D6: Convective instability | E6: Q3268911 | G6: instability > state > phenomenon > observable entity > entity | H6: context | I6: context | J6: no | K6: 100 | L6: 111 | O6: ok
A7: 1006198 | B7: Harmonic mechanical excitations of steady convective instabilities: a means to get more uniform heat transfers in mixed convection flows? | C7: Convective instability | D7: Convective instability | E7: Q3268911 | G7: instability > state > property > abstract entity > entity | H7: context | I7: context | J7: no | K7: 100 | L7: 111 | O7: ok
A8: 1006198 | B8: Harmonic mechanical excitations of steady convective instabilities: a means to get more uniform heat transfers in mixed convection flows? | C8: Convective instability | D8: Convective instability | E8: Q3268911 | G8: instability > risk source > contributing factor > condition > state | H8: context | I8: context | J8: no | K8: 100 | L8: 111 | O8: ok
A9: 1006198 | B9: Harmonic mechanical excitations of steady convective instabilities: a means to get more uniform heat transfers in mixed convection flows? | C9: Convective instability | D9: Convective instability | E9: Q3268911 | G9: instability > risk source > contributing factor > occurrent > entity | H9: context | I9: context | J9: no | K9: 100 | L9: 111 | O9: ok
A10: 1006198 | B10: Harmonic mechanical excitations of steady convective instabilities: a means to get more uniform heat transfers in mixed convection flows? | C10: Rectangular channel | H10: none | I10: none | J10: no | K10: 0 | L10: 0 | O10: ok
A11: 1006198 | B11: Harmonic mechanical excitations of steady convective instabilities: a means to get more uniform heat transfers in mixed convection flows? | C11: Harmonic inlet excitation | H11: none | I11: none | J11: no | K11: 0 | L11: 0 | O11: ok
A12: 1006198 | B12: Harmonic mechanical excitations of steady convective instabilities: a means to get more uniform heat transfers in mixed convection flows? | C12: CVD | H12: none | I12: none | J12: no | K12: 0 | L12: 0 | O12: ok
A13: 1006198 | B13: Harmonic mechanical excitations of steady convective instabilities: a means to get more uniform heat transfers in mixed convection flows? | C13: 3D numerical simulations | H13: none | I13: none | J13: no | K13: 0 | L13: 0 | O13: ok
A14: 1006198 | B14: Harmonic mechanical excitations of steady convective instabilities: a means to get more uniform heat transfers in mixed convection flows? | C14: Design of experiments | D14: Design of experiments | E14: Q18465858 | H14: context | I14: context | J14: no | K14: 100 | L14: 113 | O14: Ok | P14: No descrption defined | Q14: Correct: Q2334061
A15: 1025697 | B15: Identification of a new pseudo-binary hydroxide during calendar corrosion of (La, Mg)2Ni7-type hydrogen storage alloys for Nickel-Metal Hydride batteries | C15: Corrosion | D15: Corrosion | E15: Q5173028 | H15: context | I15: context | J15: no | K15: 100 | L15: 112 | M15: Q169930 | N15: extended play | O15: Wrong | P15: extended play by Front Line Assembly | Q15: Correct: Q137056
A16: 1025697 | B16: Identification of a new pseudo-binary hydroxide during calendar corrosion of (La, Mg)2Ni7-type hydrogen storage alloys for Nickel-Metal Hydride batteries | C16: Ni-MH batteries | H16: none | I16: none | J16: no | K16: 0 | L16: 0 | O16: ok
A17: 1025697 | B17: Identification of a new pseudo-binary hydroxide during calendar corrosion of (La, Mg)2Ni7-type hydrogen storage alloys for Nickel-Metal Hydride batteries | C17: Raman micro spectroscopy | H17: none | I17: none | J17: no | K17: 0 | L17: 0 | O17: ok
A18: 1025697 | B18: Identification of a new pseudo-binary hydroxide during calendar corrosion of (La, Mg)2Ni7-type hydrogen storage alloys for Nickel-Metal Hydride batteries | C18: TEM | D18: Tem | E18: Q36531 | F18: 12167223r | G18: Gurunsi > Gur > Voltaâ€“Congo > Atlanticâ€“Congo > Nigerâ€“Congo | H18: exact_label | I18: exact_label | J18: no | K18: 100 | L18: 50 | M18: Q1288568;Q34770 | N18: modern language;language | O18: Ok | P18: transmission electron microscopy | Q18: Correct: Q110779037
A19: 1025697 | B19: Identification of a new pseudo-binary hydroxide during calendar corrosion of (La, Mg)2Ni7-type hydrogen storage alloys for Nickel-Metal Hydride batteries | C19: TEM | D19: Tem | E19: Q36531 | F19: 12167223r | G19: Gurunsi > Gur > Nigerâ€“Congo > human language > language | H19: exact_label | I19: exact_label | J19: no | K19: 100 | L19: 50 | M19: Q1288568;Q34770 | N19: modern language;language | O19: Wrong
A20: 1025697 | B20: Identification of a new pseudo-binary hydroxide during calendar corrosion of (La, Mg)2Ni7-type hydrogen storage alloys for Nickel-Metal Hydride batteries | C20: Combination of techniques | H20: none | I20: none | J20: no | K20: 0 | L20: 0 | O20: ok
A21: 1060481 | B21: Ï€-Conjugated sulfonium-based photoacid generators: an integrated molecular approach for efficient one and two-photon polymerization | C21: 20902069 | H21: none | I21: none | J21: no | K21: 0 | L21: 0 | O21: ok
A22: 1060481 | B22: Ï€-Conjugated sulfonium-based photoacid generators: an integrated molecular approach for efficient one and two-photon polymerization | C22: Nsfc | H22: none | I22: none | J22: yes | K22: 0 | L22: 0 | O22: ok
A23: 1060481 | B23: Ï€-Conjugated sulfonium-based photoacid generators: an integrated molecular approach for efficient one and two-photon polymerization | C23: National natural science foundation of china | D23: National Natural Science Foundation of China | E23: Q4501917 | H23: exact_label | I23: exact_label | J23: no | K23: 100 | L23: 50 | M23: Q327333;Q45400320;Q5509032;Q98675100 | N23: open-access publisher;government agency;funding body;vice-ministerial level institution | O23: ok
A24: 1060481 | B24: Ï€-Conjugated sulfonium-based photoacid generators: an integrated molecular approach for efficient one and two-photon polymerization | C24: 21074094 | H24: none | I24: none | J24: no | K24: 0 | L24: 0 | O24: ok
A25: 1060481 | B25: Ï€-Conjugated sulfonium-based photoacid generators: an integrated molecular approach for efficient one and two-photon polymerization | C25: 51173134 | H25: none | I25: none | J25: no | K25: 0 | L25: 0 | O25: ok
A26: 1064801 | B26: Nucleophilic or Electrophilic Interactions of C2 with HX systems (X=F, Cl, Br) | C26: Potential curves | H26: none | I26: none | J26: no | K26: 0 | L26: 0 | O26: ok
A27: 1064801 | B27: Nucleophilic or Electrophilic Interactions of C2 with HX systems (X=F, Cl, Br) | C27: Long range interactions | H27: none | I27: none | J27: no | K27: 0 | L27: 0 | O27: ok
A28: 1064801 | B28: Nucleophilic or Electrophilic Interactions of C2 with HX systems (X=F, Cl, Br) | C28: Ab-initio calculations | H28: none | I28: none | J28: no | K28: 0 | L28: 0 | O28: ok
A29: 1064801 | B29: Nucleophilic or Electrophilic Interactions of C2 with HX systems (X=F, Cl, Br) | C29: Hydrogen halides | D29: hydrogen halide | E29: Q1572088 | G29: halide > ionic compound > chemical compound > pure substance > chemical substance | H29: exact_label | I29: exact_label | J29: no | K29: 100 | L29: 50 | M29: Q47154513 | N29: structural class of chemical entities | O29: ok
A30: 1064801 | B30: Nucleophilic or Electrophilic Interactions of C2 with HX systems (X=F, Cl, Br) | C30: Hydrogen halides | D30: hydrogen halide | E30: Q1572088 | G30: halide > halogen compound > chemical compound > pure substance > chemical substance | H30: exact_label | I30: exact_label | J30: no | K30: 100 | L30: 50 | M30: Q47154513 | N30: structural class of chemical entities | O30: ok
A31: 1064801 | B31: Nucleophilic or Electrophilic Interactions of C2 with HX systems (X=F, Cl, Br) | C31: Hydrogen halides | D31: hydrogen halide | E31: Q1572088 | G31: hydrogen compound > chemical compound > pure substance > chemical substance > chemical entity | H31: exact_label | I31: exact_label | J31: no | K31: 100 | L31: 50 | M31: Q47154513 | N31: structural class of chemical entities | O31: ok
A32: 1064801 | B32: Nucleophilic or Electrophilic Interactions of C2 with HX systems (X=F, Cl, Br) | C32: Hydrogen halides | D32: hydrogen halide | E32: Q1572088 | G32: hydrogen compound > chemical compound > pure substance > chemical substance > substance | H32: exact_label | I32: exact_label | J32: no | K32: 100 | L32: 50 | M32: Q47154513 | N32: structural class of chemical entities | O32: ok
A33: 1064801 | B33: Nucleophilic or Electrophilic Interactions of C2 with HX systems (X=F, Cl, Br) | C33: Hydrogen halides | D33: hydrogen halide | E33: Q1572088 | G33: mineral acid > acid > chemical compound > pure substance > chemical substance | H33: exact_label | I33: exact_label | J33: no | K33: 100 | L33: 50 | M33: Q47154513 | N33: structural class of chemical entities | O33: ok
A34: 1064801 | B34: Nucleophilic or Electrophilic Interactions of C2 with HX systems (X=F, Cl, Br) | C34: Hydrogen halides | D34: hydrogen halide | E34: Q1572088 | G34: mineral acid > inorganic compound > chemical compound > pure substance > chemical substance | H34: exact_label | I34: exact_label | J34: no | K34: 100 | L34: 50 | M34: Q47154513 | N34: structural class of chemical entities | O34: ok
A35: 1064801 | B35: Nucleophilic or Electrophilic Interactions of C2 with HX systems (X=F, Cl, Br) | C35: Hydrogen halides | D35: hydrogen halide | E35: Q1572088 | G35: mineral acid > inorganic compound > inorganic substance > chemical substance > chemical entity | H35: exact_label | I35: exact_label | J35: no | K35: 100 | L35: 50 | M35: Q47154513 | N35: structural class of chemical entities | O35: ok
A36: 1064801 | B36: Nucleophilic or Electrophilic Interactions of C2 with HX systems (X=F, Cl, Br) | C36: Hydrogen halides | D36: hydrogen halide | E36: Q1572088 | G36: mineral acid > inorganic compound > inorganic substance > chemical substance > substance | H36: exact_label | I36: exact_label | J36: no | K36: 100 | L36: 50 | M36: Q47154513 | N36: structural class of chemical entities | O36: ok
A37: 1064801 | B37: Nucleophilic or Electrophilic Interactions of C2 with HX systems (X=F, Cl, Br) | C37: Hydrogen halides | D37: hydrogen halide | E37: Q1572088 | G37: monoprotic acid > acid > chemical compound > pure substance > chemical substance | H37: exact_label | I37: exact_label | J37: no | K37: 100 | L37: 50 | M37: Q47154513 | N37: structural class of chemical entities | O37: ok
A38: 1067996 | B38: In situ analysis of Titan's tholins by Laser 2 steps Desorption Ionisation | C38: 5210 PLANETARY SCIENCES ASTROBIOLOGY Planetary atmospheres | H38: none | I38: none | J38: no | K38: 0 | L38: 0 | O38: ok
A39: 1067996 | B39: In situ analysis of Titan's tholins by Laser 2 steps Desorption Ionisation | C39: Clouds | D39: Clouds | E39: Q110548120 | H39: context | I39: context | J39: no | K39: 100 | L39: 114 | M39: Q11060274;Q18218093;Q838948 | N39: print;etching print;work of art | O39: Wrong
A40: 1067996 | B40: In situ analysis of Titan's tholins by Laser 2 steps Desorption Ionisation | C40: And hazes | H40: none | I40: none | J40: no | K40: 0 | L40: 0 | O40: ok
...

Sheet Wikidata_upec_civil_20
A1: docid | B1: title | C1: keyword | D1: wikidata_label | E1: wikidata_qid | F1: bnf_id | G1: p279_path | H1: retry_source | I1: match_stage | J1: is_disambiguation | K1: label_similarity | L1: match_score | M1: p31_types | N1: p31_label | O1: Check | S1: clean | T1: Sclean
A2: 1002652 | B2: Urban stormwater source control policies: why and how? | C2: Stormwater management | H2: none | I2: none | J2: no | K2: 0 | L2: 0 | P2: csv empty, no info on wikidata | Q2: yes | S2: =LOWER(TRIM(CLEAN(Q2))) -> yes | T2: =IF(S2="","",LOWER(TRIM(S2))) -> yes
A3: 1002652 | B3: Urban stormwater source control policies: why and how? | C3: Urban areas | D3: urban area | E3: Q702492 | G3: human settlement > populated place > region > geographical feature > geographic entity | H3: exact_label | I3: exact_label | J3: no | K3: 100 | L3: 50 | Q3: yes | S3: =LOWER(TRIM(CLEAN(Q3))) -> yes | T3: =IF(S3="","",LOWER(TRIM(S3))) -> yes
A4: 1002652 | B4: Urban stormwater source control policies: why and how? | C4: Urban areas | D4: urban area | E4: Q702492 | G4: human settlement > populated place > region > geographical feature > concrete object | H4: exact_label | I4: exact_label | J4: no | K4: 100 | L4: 50 | Q4: yes | S4: =LOWER(TRIM(CLEAN(Q4))) -> yes | T4: =IF(S4="","",LOWER(TRIM(S4))) -> yes
A5: 1002652 | B5: Urban stormwater source control policies: why and how? | C5: Urban areas | D5: urban area | E5: Q702492 | G5: human settlement > populated place > region > geographical feature > physical location | H5: exact_label | I5: exact_label | J5: no | K5: 100 | L5: 50 | Q5: yes | S5: =LOWER(TRIM(CLEAN(Q5))) -> yes | T5: =IF(S5="","",LOWER(TRIM(S5))) -> yes
A6: 1002652 | B6: Urban stormwater source control policies: why and how? | C6: Urban areas | D6: urban area | E6: Q702492 | G6: human settlement > populated place > artificial geographic entity > geographic entity > geolocatable entity | H6: exact_label | I6: exact_label | J6: no | K6: 100 | L6: 50 | Q6: yes | S6: =LOWER(TRIM(CLEAN(Q6))) -> yes | T6: =IF(S6="","",LOWER(TRIM(S6))) -> yes | U6: 1st round | V6: Field | W6: Total articles | X6: Total keywords | Y6: Correct Wikidata label | Z6: Incorrect Wikidata label | AA6: # QID in Wikidata | AB6: # BNF_Id | AC6: % Correct Wikidata label | AD6: % Incorrect Wikidata label | AE6: % # QID in Wikidata | AF6: % # BNF_Id
A7: 1002652 | B7: Urban stormwater source control policies: why and how? | C7: Urban areas | D7: urban area | E7: Q702492 | G7: human settlement > populated place > artificial geographic entity > geographic entity > region of space | H7: exact_label | I7: exact_label | J7: no | K7: 100 | L7: 50 | Q7: yes | S7: =LOWER(TRIM(CLEAN(Q7))) -> yes | T7: =IF(S7="","",LOWER(TRIM(S7))) -> yes | U7: Sallay | V7: Civil Engineering | W7: 20 | X7: {=COUNTA(_xlfn.UNIQUE(_xlfn._xlws.FILTER(C2:C389, C2:C389<>"")))} -> 93 | Y7: {=COUNTA(_xlfn.UNIQUE(_xlfn._xlws.FILTER(C2:C389 & E2:E389, T2:T389="yes")))} -> 67 | Z7: {=COUNTA(_xlfn.UNIQUE(_xlfn._xlws.FILTER(C2:C389 & E2:E389, T2:T389="wrong")))} -> 26 | AA7: {=COUNTA(_xlfn.UNIQUE(_xlfn._xlws.FILTER(E2:E389, E2:E389<>"")))} -> 43 | AB7: {=COUNTA(_xlfn.UNIQUE(_xlfn._xlws.FILTER(F2:F389, F2:F389<>"")))} -> 7 | AC7: =Y7 / (Y7 + Z7) -> 0.72043011 | AD7: =Z7 / (Y7 + Z7) -> 0.27956989 | AE7: =AA7 / X7 -> 0.46236559 | AF7: =AB7 / X7 -> 0.075268817
A8: 1002652 | B8: Urban stormwater source control policies: why and how? | C8: Urban areas | D8: urban area | E8: Q702492 | G8: human settlement > populated place > artificial geographic entity > artificial object > object | H8: exact_label | I8: exact_label | J8: no | K8: 100 | L8: 50 | Q8: yes | S8: =LOWER(TRIM(CLEAN(Q8))) -> yes | T8: =IF(S8="","",LOWER(TRIM(S8))) -> yes
A9: 1002652 | B9: Urban stormwater source control policies: why and how? | C9: Urban areas | D9: urban area | E9: Q702492 | G9: human settlement > group of structures or buildings > group of artificial physical objects > group of physical objects > group or class of physical objects | H9: exact_label | I9: exact_label | J9: no | K9: 100 | L9: 50 | Q9: yes | S9: =LOWER(TRIM(CLEAN(Q9))) -> yes | T9: =IF(S9="","",LOWER(TRIM(S9))) -> yes
A10: 1002652 | B10: Urban stormwater source control policies: why and how? | C10: Urban areas | D10: urban area | E10: Q702492 | G10: human settlement > group of structures or buildings > group of artificial physical objects > group of physical objects > group | H10: exact_label | I10: exact_label | J10: no | K10: 100 | L10: 50 | Q10: yes | S10: =LOWER(TRIM(CLEAN(Q10))) -> yes | T10: =IF(S10="","",LOWER(TRIM(S10))) -> yes
A11: 1002652 | B11: Urban stormwater source control policies: why and how? | C11: Urban areas | D11: urban area | E11: Q702492 | G11: human settlement > group of structures or buildings > group of geographic locations > group > set | H11: exact_label | I11: exact_label | J11: no | K11: 100 | L11: 50 | Q11: yes | S11: =LOWER(TRIM(CLEAN(Q11))) -> yes | T11: =IF(S11="","",LOWER(TRIM(S11))) -> yes
A12: 1002652 | B12: Urban stormwater source control policies: why and how? | C12: Urban areas | D12: urban area | E12: Q702492 | G12: human settlement > group of structures or buildings > group of works > group > set | H12: exact_label | I12: exact_label | J12: no | K12: 100 | L12: 50 | Q12: yes | S12: =LOWER(TRIM(CLEAN(Q12))) -> yes | T12: =IF(S12="","",LOWER(TRIM(S12))) -> yes
A13: 1002652 | B13: Urban stormwater source control policies: why and how? | C13: Urban areas | D13: urban area | E13: Q702492 | G13: human settlement > group of structures or buildings > group of works > work > artificial object | H13: exact_label | I13: exact_label | J13: no | K13: 100 | L13: 50 | Q13: yes | S13: =LOWER(TRIM(CLEAN(Q13))) -> yes | T13: =IF(S13="","",LOWER(TRIM(S13))) -> yes
A14: 1002652 | B14: Urban stormwater source control policies: why and how? | C14: Urban areas | D14: urban area | E14: Q702492 | G14: human settlement > group of structures or buildings > group of works > work > cultural artifact | H14: exact_label | I14: exact_label | J14: no | K14: 100 | L14: 50 | Q14: yes | S14: =LOWER(TRIM(CLEAN(Q14))) -> yes | T14: =IF(S14="","",LOWER(TRIM(S14))) -> yes
A15: 1002652 | B15: Urban stormwater source control policies: why and how? | C15: Urban areas | D15: urban area | E15: Q702492 | G15: human settlement > group of structures or buildings > architectural structure > artificial physical structure > physical structure | H15: exact_label | I15: exact_label | J15: no | K15: 100 | L15: 50 | Q15: yes | S15: =LOWER(TRIM(CLEAN(Q15))) -> yes | T15: =IF(S15="","",LOWER(TRIM(S15))) -> yes
A16: 1002652 | B16: Urban stormwater source control policies: why and how? | C16: Urban areas | D16: urban area | E16: Q702492 | G16: human settlement > group of structures or buildings > architectural structure > artificial physical structure > artificial physical object | H16: exact_label | I16: exact_label | J16: no | K16: 100 | L16: 50 | Q16: yes | S16: =LOWER(TRIM(CLEAN(Q16))) -> yes | T16: =IF(S16="","",LOWER(TRIM(S16))) -> yes
A17: 1002652 | B17: Urban stormwater source control policies: why and how? | C17: Urban areas | D17: urban area | E17: Q702492 | G17: human settlement > group of structures or buildings > architectural structure > artificial physical structure > technical system | H17: exact_label | I17: exact_label | J17: no | K17: 100 | L17: 50 | Q17: yes | S17: =LOWER(TRIM(CLEAN(Q17))) -> yes | T17: =IF(S17="","",LOWER(TRIM(S17))) -> yes
A18: 1002652 | B18: Urban stormwater source control policies: why and how? | C18: Urban areas | D18: urban area | E18: Q702492 | G18: human settlement > group of structures or buildings > architectural structure > fixed construction > geographical feature | H18: exact_label | I18: exact_label | J18: no | K18: 100 | L18: 50 | Q18: yes | S18: =LOWER(TRIM(CLEAN(Q18))) -> yes | T18: =IF(S18="","",LOWER(TRIM(S18))) -> yes
A19: 1002652 | B19: Urban stormwater source control policies: why and how? | C19: Urban areas | D19: urban area | E19: Q702492 | G19: human settlement > group of structures or buildings > architectural structure > fixed construction > artificial physical object | H19: exact_label | I19: exact_label | J19: no | K19: 100 | L19: 50 | Q19: yes | S19: =LOWER(TRIM(CLEAN(Q19))) -> yes | T19: =IF(S19="","",LOWER(TRIM(S19))) -> yes
... A22: 1002652 | B22: Urban stormwater source control policies: why and how? | C22: Urban areas | D22: urban area | E22: Q702492 | G22: human settlement > group of structures or buildings > architectural structure > E25 Human-Made Feature > artificial physical object | H22: exact_label | I22: exact_label | J22: no | K22: 100 | L22: 50 | Q22: yes | S22: =LOWER(TRIM(CLEAN(Q22))) -> yes | T22: =IF(S22="","",LOWER(TRIM(S22))) -> yes
A23: 1002652 | B23: Urban stormwater source control policies: why and how? | C23: Source control | H23: none | I23: none | J23: yes | K23: 0 | L23: 0 | Q23: yes | S23: =LOWER(TRIM(CLEAN(Q23))) -> yes | T23: =IF(S23="","",LOWER(TRIM(S23))) -> yes
A24: 1002652 | B24: Urban stormwater source control policies: why and how? | C24: Policy-making | H24: none | I24: none | J24: no | K24: 0 | L24: 0 | Q24: yes | S24: =LOWER(TRIM(CLEAN(Q24))) -> yes | T24: =IF(S24="","",LOWER(TRIM(S24))) -> yes
A25: 1015767 | B25: Clarification about component mode synthesis methods for substructures with physical flexible interfaces | C25: Component mode synthesis | H25: none | I25: none | J25: no | K25: 0 | L25: 0 | Q25: yes | S25: =LOWER(TRIM(CLEAN(Q25))) -> yes | T25: =IF(S25="","",LOWER(TRIM(S25))) -> yes
A26: 1015767 | B26: Clarification about component mode synthesis methods for substructures with physical flexible interfaces | C26: Dynamic substructuring | D26: dynamic substructuring | E26: Q25112238 | H26: context | I26: context | J26: no | K26: 95.5 | L26: 107.3 | P26: found but no description was defined | Q26: wrong | S26: =LOWER(TRIM(CLEAN(Q26))) -> wrong | T26: =IF(S26="","",LOWER(TRIM(S26))) -> wrong
A27: 1015767 | B27: Clarification about component mode synthesis methods for substructures with physical flexible interfaces | C27: Flexible interface | H27: none | I27: none | J27: no | K27: 0 | L27: 0 | Q27: yes | S27: =LOWER(TRIM(CLEAN(Q27))) -> yes | T27: =IF(S27="","",LOWER(TRIM(S27))) -> yes
A28: 1015767 | B28: Clarification about component mode synthesis methods for substructures with physical flexible interfaces | C28: Computational mechanics | D28: computational mechanics | E28: Q919765 | G28: mechanics > physics > natural science > science > knowledge system | H28: context | I28: context | J28: no | K28: 95.7 | L28: 113.4 | Q28: yes | S28: =LOWER(TRIM(CLEAN(Q28))) -> yes | T28: =IF(S28="","",LOWER(TRIM(S28))) -> yes
A29: 1015767 | B29: Clarification about component mode synthesis methods for substructures with physical flexible interfaces | C29: Computational mechanics | D29: computational mechanics | E29: Q919765 | G29: mechanics > physics > natural science > science > knowledge | H29: context | I29: context | J29: no | K29: 95.7 | L29: 113.4 | Q29: yes | S29: =LOWER(TRIM(CLEAN(Q29))) -> yes | T29: =IF(S29="","",LOWER(TRIM(S29))) -> yes
A30: 1015767 | B30: Clarification about component mode synthesis methods for substructures with physical flexible interfaces | C30: Computational mechanics | D30: computational mechanics | E30: Q919765 | G30: mechanics > physics > natural science > science > outline of academic disciplines | H30: context | I30: context | J30: no | K30: 95.7 | L30: 113.4 | Q30: yes | S30: =LOWER(TRIM(CLEAN(Q30))) -> yes | T30: =IF(S30="","",LOWER(TRIM(S30))) -> yes
A31: 1015767 | B31: Clarification about component mode synthesis methods for substructures with physical flexible interfaces | C31: Computational mechanics | D31: computational mechanics | E31: Q919765 | G31: mechanics > physics > natural science > science > epistemology | H31: context | I31: context | J31: no | K31: 95.7 | L31: 113.4 | Q31: yes | S31: =LOWER(TRIM(CLEAN(Q31))) -> yes | T31: =IF(S31="","",LOWER(TRIM(S31))) -> yes
A32: 1015767 | B32: Clarification about component mode synthesis methods for substructures with physical flexible interfaces | C32: Computational mechanics | D32: computational mechanics | E32: Q919765 | G32: mechanics > physics > natural science > science > research | H32: context | I32: context | J32: no | K32: 95.7 | L32: 113.4 | Q32: yes | S32: =LOWER(TRIM(CLEAN(Q32))) -> yes | T32: =IF(S32="","",LOWER(TRIM(S32))) -> yes
A33: 1015767 | B33: Clarification about component mode synthesis methods for substructures with physical flexible interfaces | C33: Computational mechanics | D33: computational mechanics | E33: Q919765 | G33: mechanics > physics > natural science > science > logic | H33: context | I33: context | J33: no | K33: 95.7 | L33: 113.4 | Q33: yes | S33: =LOWER(TRIM(CLEAN(Q33))) -> yes | T33: =IF(S33="","",LOWER(TRIM(S33))) -> yes
A34: 1015767 | B34: Clarification about component mode synthesis methods for substructures with physical flexible interfaces | C34: Computational mechanics | D34: computational mechanics | E34: Q919765 | G34: mechanics > physics > natural science > science > intellectual activity | H34: context | I34: context | J34: no | K34: 95.7 | L34: 113.4 | Q34: yes | S34: =LOWER(TRIM(CLEAN(Q34))) -> yes | T34: =IF(S34="","",LOWER(TRIM(S34))) -> yes
A35: 1015767 | B35: Clarification about component mode synthesis methods for substructures with physical flexible interfaces | C35: Computational mechanics | D35: computational mechanics | E35: Q919765 | G35: mechanics > physics > physical sciences > natural science > science | H35: context | I35: context | J35: no | K35: 95.7 | L35: 113.4 | Q35: yes | S35: =LOWER(TRIM(CLEAN(Q35))) -> yes | T35: =IF(S35="","",LOWER(TRIM(S35))) -> yes
A36: 1015767 | B36: Clarification about component mode synthesis methods for substructures with physical flexible interfaces | C36: Computational mechanics | D36: computational mechanics | E36: Q919765 | G36: computational physics > computational science > applied mathematics > mathematics > natural science | H36: context | I36: context | J36: no | K36: 95.7 | L36: 113.4 | Q36: yes | S36: =LOWER(TRIM(CLEAN(Q36))) -> yes | T36: =IF(S36="","",LOWER(TRIM(S36))) -> yes
A37: 1015767 | B37: Clarification about component mode synthesis methods for substructures with physical flexible interfaces | C37: Computational mechanics | D37: computational mechanics | E37: Q919765 | G37: computational physics > computational science > computer science > formal science > exact science | H37: context | I37: context | J37: no | K37: 95.7 | L37: 113.4 | Q37: yes | S37: =LOWER(TRIM(CLEAN(Q37))) -> yes | T37: =IF(S37="","",LOWER(TRIM(S37))) -> yes
A38: 1015767 | B38: Clarification about component mode synthesis methods for substructures with physical flexible interfaces | C38: Computational mechanics | D38: computational mechanics | E38: Q919765 | G38: computational physics > physics > natural science > science > knowledge system | H38: context | I38: context | J38: no | K38: 95.7 | L38: 113.4 | Q38: yes | S38: =LOWER(TRIM(CLEAN(Q38))) -> yes | T38: =IF(S38="","",LOWER(TRIM(S38))) -> yes
A39: 1015767 | B39: Clarification about component mode synthesis methods for substructures with physical flexible interfaces | C39: Computational mechanics | D39: computational mechanics | E39: Q919765 | G39: computational physics > physics > natural science > science > knowledge | H39: context | I39: context | J39: no | K39: 95.7 | L39: 113.4 | Q39: yes | S39: =LOWER(TRIM(CLEAN(Q39))) -> yes | T39: =IF(S39="","",LOWER(TRIM(S39))) -> yes
... A45: 1015767 | B45: Clarification about component mode synthesis methods for substructures with physical flexible interfaces | C45: Computational mechanics | D45: computational mechanics | E45: Q919765 | G45: computational physics > physics > physical sciences > natural science > science | H45: context | I45: context | J45: no | K45: 95.7 | L45: 113.4 | Q45: yes | S45: =LOWER(TRIM(CLEAN(Q45))) -> yes | T45: =IF(S45="","",LOWER(TRIM(S45))) -> yes
A46: 1061949 | B46: Reduced-order model for the dynamical analysis of complex structures with a high modal density | C46: Reduced-order model | H46: none | I46: none | J46: no | K46: 0 | L46: 0 | Q46: yes | S46: =LOWER(TRIM(CLEAN(Q46))) -> yes | T46: =IF(S46="","",LOWER(TRIM(S46))) -> yes
A47: 1061949 | B47: Reduced-order model for the dynamical analysis of complex structures with a high modal density | C47: Structural dynamics | D47: structural dynamics | E47: Q811197 | G47: structural analysis > analysis > inquiry > seeking > activity | H47: exact_label | I47: exact_label | J47: no | K47: 100 | L47: 80 | M47: Q11862829 | N47: academic discipline | Q47: yes | S47: =LOWER(TRIM(CLEAN(Q47))) -> yes | T47: =IF(S47="","",LOWER(TRIM(S47))) -> yes
...

Sheet Wikidata_upec_civil_20_part2
A1: docid | B1: title | C1: keyword | D1: wikidata_label | E1: wikidata_qid | F1: bnf_id | G1: p279_path | H1: retry_source | I1: match_stage | J1: is_disambiguation | K1: label_similarity | L1: match_score | M1: p31_types | N1: p31_label | O1: wikidata matched | P1: bnf matched | Q1: remarks | R1: % QID matched | S1: % BnF matched | U1: keywords | V1: # of KEYWORDS
A2: 1131185 | B2: Les Â« riviÃ¨res de pierres Â» : une formation en marge des catÃ©gories classiques. Questions posÃ©es dans le cas du massif du MÃ©zenc (Velay oriental, Sud-Est du Massif central, France). | C2: French Massif central | H2: none | I2: none | J2: no | K2: 0 | L2: 0 | O2: YES | P2: YES | R2: =COUNTIF(O2:O39,"*YES*")/COUNTA(O2:O39) -> 0.92105263 | S2: =COUNTIF(P2:P39,"*YES*")/COUNTA(P2:P39) -> 0.92105263 | U2: {=_xlfn.UNIQUE(C2:C192)} -> French Massif central | V2: =COUNTIF(C2:C192, U2) -> 1 | X2: Unique Keywords | Y2: {=COUNTA(_xlfn.UNIQUE(_xlfn._xlws.FILTER(C2:C192,C2:C192<>"")))} -> 48
A3: 1131185 | B3: Les Â« riviÃ¨res de pierres Â» : une formation en marge des catÃ©gories classiques. Questions posÃ©es dans le cas du massif du MÃ©zenc (Velay oriental, Sud-Est du Massif central, France). | C3: Blockstream | D3: Blockstream | E3: Q24909896 | H3: context | I3: context | J3: no | K3: 100 | L3: 110 | M3: Q167037 | N3: corporation | O3: NO | P3: NO | Q3: mismatched on the context | U3: Blockstream | V3: =COUNTIF(C3:C193, U3) -> 1 | X3: Unique QID | Y3: {=COUNTA(_xlfn.UNIQUE(_xlfn._xlws.FILTER(E2:E192,(E2:E192<>"")*(E2:E192<>"none"))))} -> 17
A4: 1131185 | B4: Les Â« riviÃ¨res de pierres Â» : une formation en marge des catÃ©gories classiques. Questions posÃ©es dans le cas du massif du MÃ©zenc (Velay oriental, Sud-Est du Massif central, France). | C4: Rock glacier | D4: rock glacier | E4: Q884736 | F4: 13507719g | G4: glacier > ice cover > body of water > region > geographical feature | H4: exact_label | I4: exact_label | J4: no | K4: 100 | L4: 50 | O4: YES | P4: YES | U4: Rock glacier | V4: =COUNTIF(C4:C194, U4) -> 29 | X4: % QID (vs unique keywords) | Y4: {=COUNTA(_xlfn.UNIQUE(_xlfn._xlws.FILTER(E2:E192,(E2:E192<>"")*(E2:E192<>"none")))) / COUNTA(_xlfn.UNIQUE(_xlfn._xlws.FILTER(C2:C192,C2:C192<>"")))} -> 0.35416667
A5: 1131185 | B5: Les Â« riviÃ¨res de pierres Â» : une formation en marge des catÃ©gories classiques. Questions posÃ©es dans le cas du massif du MÃ©zenc (Velay oriental, Sud-Est du Massif central, France). | C5: Rock glacier | D5: rock glacier | E5: Q884736 | F5: 13507719g | G5: glacier > ice cover > body of water > physico-geographical object > geographical feature | H5: exact_label | I5: exact_label | J5: no | K5: 100 | L5: 50 | O5: YES | P5: YES | U5: Periglacial morphology and process | V5: =COUNTIF(C5:C195, U5) -> 1 | X5: Unique BnF | Y5: {=COUNTA(_xlfn.UNIQUE(_xlfn._xlws.FILTER(F2:F192,(F2:F192<>"")*(F2:F192<>"none"))))} -> 2
A6: 1131185 | B6: Les Â« riviÃ¨res de pierres Â» : une formation en marge des catÃ©gories classiques. Questions posÃ©es dans le cas du massif du MÃ©zenc (Velay oriental, Sud-Est du Massif central, France). | C6: Rock glacier | D6: rock glacier | E6: Q884736 | F6: 13507719g | G6: glacier > ice cover > body of water > physico-geographical object > physical object | H6: exact_label | I6: exact_label | J6: no | K6: 100 | L6: 50 | O6: YES | P6: YES | U6: Pleistocene | V6: =COUNTIF(C6:C196, U6) -> 1 | X6: %BnF ID (vs unique keywords) | Y6: {=COUNTA(_xlfn.UNIQUE(_xlfn._xlws.FILTER(E2:F192,(F2:F192<>"")*(F2:F192<>"none")))) / COUNTA(_xlfn.UNIQUE(_xlfn._xlws.FILTER(C2:C192,C2:C192<>"")))} -> 0.083333333
A7: 1131185 | B7: Les Â« riviÃ¨res de pierres Â» : une formation en marge des catÃ©gories classiques. Questions posÃ©es dans le cas du massif du MÃ©zenc (Velay oriental, Sud-Est du Massif central, France). | C7: Rock glacier | D7: rock glacier | E7: Q884736 | F7: 13507719g | G7: glacier > ice cover > body of water > habitat > region | H7: exact_label | I7: exact_label | J7: no | K7: 100 | L7: 50 | O7: YES | P7: YES | U7: Late Glacial | V7: =COUNTIF(C7:C197, U7) -> 1 | X7: %QID matched | Y7: =COUNTIF(O2:O192,"*YES*")/COUNTA(O2:O192) -> 0.95811518
A8: 1131185 | B8: Les Â« riviÃ¨res de pierres Â» : une formation en marge des catÃ©gories classiques. Questions posÃ©es dans le cas du massif du MÃ©zenc (Velay oriental, Sud-Est du Massif central, France). | C8: Rock glacier | D8: rock glacier | E8: Q884736 | F8: 13507719g | G8: glacier > ice cover > body of water > habitat > natural environment | H8: exact_label | I8: exact_label | J8: no | K8: 100 | L8: 50 | O8: YES | P8: YES | U8: Eastern Velay | V8: =COUNTIF(C8:C198, U8) -> 1 | X8: %BnF matched | Y8: =COUNTIF(P2:P192,"*YES*")/COUNTA(P2:P192) -> 0.98113208
A9: 1131185 | B9: Les Â« riviÃ¨res de pierres Â» : une formation en marge des catÃ©gories classiques. Questions posÃ©es dans le cas du massif du MÃ©zenc (Velay oriental, Sud-Est du Massif central, France). | C9: Rock glacier | D9: rock glacier | E9: Q884736 | F9: 13507719g | G9: glacier > ice cover > glacial landform > landform > geomorphological unit | H9: exact_label | I9: exact_label | J9: no | K9: 100 | L9: 50 | O9: YES | P9: YES | U9: MÃ©zenc | V9: =COUNTIF(C9:C199, U9) -> 1
A10: 1131185 | B10: Les Â« riviÃ¨res de pierres Â» : une formation en marge des catÃ©gories classiques. Questions posÃ©es dans le cas du massif du MÃ©zenc (Velay oriental, Sud-Est du Massif central, France). | C10: Rock glacier | D10: rock glacier | E10: Q884736 | F10: 13507719g | G10: glacier > ice cover > glacial landform > landform > geographical feature | H10: exact_label | I10: exact_label | J10: no | K10: 100 | L10: 50 | O10: YES | P10: YES | U10: Morphologie et processus pÃ©riglaciaires | V10: =COUNTIF(C10:C200, U10) -> 1
A11: 1131185 | B11: Les Â« riviÃ¨res de pierres Â» : une formation en marge des catÃ©gories classiques. Questions posÃ©es dans le cas du massif du MÃ©zenc (Velay oriental, Sud-Est du Massif central, France). | C11: Rock glacier | D11: rock glacier | E11: Q884736 | F11: 13507719g | G11: glacier > ice cover > glacial landform > landform > geographic location | H11: exact_label | I11: exact_label | J11: no | K11: 100 | L11: 50 | O11: YES | P11: YES | U11: RiviÃ¨re de pierres | V11: =COUNTIF(C11:C201, U11) -> 1 | W11: Total articles | X11: Total keywords | Y11: Correct Wikidata label | Z11: Incorrect Wikidata label | AA11: # QID in Wikidata | AB11: # BNF_Id | AC11: % Correct Wikidata label | AD11: % Incorrect Wikidata label | AE11: % # QID in Wikidata | AF11: % # BNF_Id
A12: 1131185 | B12: Les Â« riviÃ¨res de pierres Â» : une formation en marge des catÃ©gories classiques. Questions posÃ©es dans le cas du massif du MÃ©zenc (Velay oriental, Sud-Est du Massif central, France). | C12: Rock glacier | D12: rock glacier | E12: Q884736 | F12: 13507719g | G12: glacier > perennial ice or snowâ€covered land > landform > geomorphological unit > natural geographic object | H12: exact_label | I12: exact_label | J12: no | K12: 100 | L12: 50 | O12: YES | P12: YES | U12: Glacier rocheux | V12: =COUNTIF(C12:C202, U12) -> 29 | W12: {=COUNTA(_xlfn.UNIQUE(_xlfn._xlws.FILTER(B2:B192, B2:B192<>"")))} -> 9 | X12: {=COUNTA(_xlfn.UNIQUE(_xlfn._xlws.FILTER(C2:C192, C2:C192<>"")))} -> 48 | Y12: {=COUNTA(_xlfn.UNIQUE(_xlfn._xlws.FILTER(C2:C192 & E2:E192, O2:O192="YES")))} -> 41 | Z12: {=COUNTA(_xlfn.UNIQUE(_xlfn._xlws.FILTER(C2:C192 & E2:E192, O2:O192="NO")))} -> 7 | AA12: {=COUNTA(_xlfn.UNIQUE(_xlfn._xlws.FILTER(E2:E192, E2:E192<>"")))} -> 17 | AB12: {=COUNTA(_xlfn.UNIQUE(_xlfn._xlws.FILTER(F2:F192, F2:F192<>"")))} -> 2 | AC12: =Y12 / (Y12 + Z12) -> 0.85416667 | AD12: =Z12 / (Y12 + Z12) -> 0.14583333 | AE12: =AA12 / X12 -> 0.35416667 | AF12: =AB12 / X12 -> 0.041666667
A13: 1131185 | B13: Les Â« riviÃ¨res de pierres Â» : une formation en marge des catÃ©gories classiques. Questions posÃ©es dans le cas du massif du MÃ©zenc (Velay oriental, Sud-Est du Massif central, France). | C13: Rock glacier | D13: rock glacier | E13: Q884736 | F13: 13507719g | G13: glacier > perennial ice or snowâ€covered land > landform > geographical feature > geographic entity | H13: exact_label | I13: exact_label | J13: no | K13: 100 | L13: 50 | O13: YES | P13: YES | U13: Velay oriental | V13: =COUNTIF(C13:C203, U13) -> 1
A14: 1131185 | B14: Les Â« riviÃ¨res de pierres Â» : une formation en marge des catÃ©gories classiques. Questions posÃ©es dans le cas du massif du MÃ©zenc (Velay oriental, Sud-Est du Massif central, France). | C14: Rock glacier | D14: rock glacier | E14: Q884736 | F14: 13507719g | G14: glacier > perennial ice or snowâ€covered land > landform > geographical feature > concrete object | H14: exact_label | I14: exact_label | J14: no | K14: 100 | L14: 50 | O14: YES | P14: YES | U14: Massif central franÃ§ais | V14: =COUNTIF(C14:C204, U14) -> 1
A15: 1131185 | B15: Les Â« riviÃ¨res de pierres Â» : une formation en marge des catÃ©gories classiques. Questions posÃ©es dans le cas du massif du MÃ©zenc (Velay oriental, Sud-Est du Massif central, France). | C15: Rock glacier | D15: rock glacier | E15: Q884736 | F15: 13507719g | G15: glacier > perennial ice or snowâ€covered land > landform > geographical feature > physical location | H15: exact_label | I15: exact_label | J15: no | K15: 100 | L15: 50 | O15: YES | P15: YES | U15: Tardiglaciaire | V15: =COUNTIF(C15:C205, U15) -> 1
A16: 1131185 | B16: Les Â« riviÃ¨res de pierres Â» : une formation en marge des catÃ©gories classiques. Questions posÃ©es dans le cas du massif du MÃ©zenc (Velay oriental, Sud-Est du Massif central, France). | C16: Rock glacier | D16: rock glacier | E16: Q884736 | F16: 13507719g | G16: glacier > perennial ice or snowâ€covered land > landform > geographic location > geographic entity | H16: exact_label | I16: exact_label | J16: no | K16: 100 | L16: 50 | O16: YES | P16: YES | U16: Dunkl kernel | V16: =COUNTIF(C16:C206, U16) -> 1
A17: 1131185 | B17: Les Â« riviÃ¨res de pierres Â» : une formation en marge des catÃ©gories classiques. Questions posÃ©es dans le cas du massif du MÃ©zenc (Velay oriental, Sud-Est du Massif central, France). | C17: Rock glacier | D17: rock glacier | E17: Q884736 | F17: 13507719g | G17: glacier > perennial ice or snowâ€covered land > landform > geographic location > physical location | H17: exact_label | I17: exact_label | J17: no | K17: 100 | L17: 50 | O17: YES | P17: YES | U17: Dihedral root systems | V17: =COUNTIF(C17:C207, U17) -> 1
A18: 1131185 | B18: Les Â« riviÃ¨res de pierres Â» : une formation en marge des catÃ©gories classiques. Questions posÃ©es dans le cas du massif du MÃ©zenc (Velay oriental, Sud-Est du Massif central, France). | C18: Rock glacier | D18: rock glacier | E18: Q884736 | F18: 13507719g | G18: frozen ground > soil > granular material > material > substance | H18: exact_label | I18: exact_label | J18: no | K18: 100 | L18: 50 | O18: YES | P18: YES | U18: Generalized Bessel function | V18: =COUNTIF(C18:C208, U18) -> 1
A19: 1131185 | B19: Les Â« riviÃ¨res de pierres Â» : une formation en marge des catÃ©gories classiques. Questions posÃ©es dans le cas du massif du MÃ©zenc (Velay oriental, Sud-Est du Massif central, France). | C19: Rock glacier | D19: rock glacier | E19: Q884736 | F19: 13507719g | G19: frozen ground > soil > granular material > material > product | H19: exact_label | I19: exact_label | J19: no | K19: 100 | L19: 50 | O19: YES | P19: YES | U19: Structural dynamics | V19: =COUNTIF(C19:C209, U19) -> 8
A20: 1131185 | B20: Les Â« riviÃ¨res de pierres Â» : une formation en marge des catÃ©gories classiques. Questions posÃ©es dans le cas du massif du MÃ©zenc (Velay oriental, Sud-Est du Massif central, France). | C20: Rock glacier | D20: rock glacier | E20: Q884736 | F20: 13507719g | G20: frozen ground > soil > granular material > continuum > physical substance | H20: exact_label | I20: exact_label | J20: no | K20: 100 | L20: 50 | O20: YES | P20: YES | U20: Model identification | V20: =COUNTIF(C20:C210, U20) -> 1
A21: 1131185 | B21: Les Â« riviÃ¨res de pierres Â» : une formation en marge des catÃ©gories classiques. Questions posÃ©es dans le cas du massif du MÃ©zenc (Velay oriental, Sud-Est du Massif central, France). | C21: Rock glacier | D21: rock glacier | E21: Q884736 | F21: 13507719g | G21: frozen ground > soil > heterogeneous mixture > mixture > chemical substance | H21: exact_label | I21: exact_label | J21: no | K21: 100 | L21: 50 | O21: YES | P21: YES | U21: Computational stochastic dynamics | V21: =COUNTIF(C21:C211, U21) -> 1
A22: 1131185 | B22: Les Â« riviÃ¨res de pierres Â» : une formation en marge des catÃ©gories classiques. Questions posÃ©es dans le cas du massif du MÃ©zenc (Velay oriental, Sud-Est du Massif central, France). | C22: Rock glacier | D22: rock glacier | E22: Q884736 | F22: 13507719g | G22: frozen ground > soil > natural system > system > collective entity | H22: exact_label | I22: exact_label | J22: no | K22: 100 | L22: 50 | O22: YES | P22: YES | U22: Mode crossing | V22: =COUNTIF(C22:C212, U22) -> 1
A23: 1131185 | B23: Les Â« riviÃ¨res de pierres Â» : une formation en marge des catÃ©gories classiques. Questions posÃ©es dans le cas du massif du MÃ©zenc (Velay oriental, Sud-Est du Massif central, France). | C23: Rock glacier | D23: rock glacier | E23: Q884736 | F23: 13507719g | G23: frozen ground > soil > natural system > system > abstract entity | H23: exact_label | I23: exact_label | J23: no | K23: 100 | L23: 50 | O23: YES | P23: YES | U23: Experimental modal analysis | V23: =COUNTIF(C23:C213, U23) -> 1
A24: 1131185 | B24: Les Â« riviÃ¨res de pierres Â» : une formation en marge des catÃ©gories classiques. Questions posÃ©es dans le cas du massif du MÃ©zenc (Velay oriental, Sud-Est du Massif central, France). | C24: Rock glacier | D24: rock glacier | E24: Q884736 | F24: 13507719g | G24: frozen ground > soil > natural system > system > object | H24: exact_label | I24: exact_label | J24: no | K24: 100 | L24: 50 | O24: YES | P24: YES | U24: Uncertainty Quantification | V24: =COUNTIF(C24:C214, U24) -> 36
... A32: 1131185 | B32: Les Â« riviÃ¨res de pierres Â» : une formation en marge des catÃ©gories classiques. Questions posÃ©es dans le cas du massif du MÃ©zenc (Velay oriental, Sud-Est du Massif central, France). | C32: Rock glacier | D32: rock glacier | E32: Q884736 | F32: 13507719g | G32: frozen ground > soil > building material > construction product > product | H32: exact_label | I32: exact_label | J32: no | K32: 100 | L32: 50 | O32: YES | P32: YES | U32: Vibration | V32: =COUNTIF(C32:C222, U32) -> 1
A33: 1131185 | B33: Les Â« riviÃ¨res de pierres Â» : une formation en marge des catÃ©gories classiques. Questions posÃ©es dans le cas du massif du MÃ©zenc (Velay oriental, Sud-Est du Massif central, France). | C33: Periglacial morphology and process | H33: none | I33: none | J33: no | K33: 0 | L33: 0 | O33: YES | P33: YES | U33: Computational Vibroacoustics | V33: =COUNTIF(C33:C223, U33) -> 1
A34: 1131185 | B34: Les Â« riviÃ¨res de pierres Â» : une formation en marge des catÃ©gories classiques. Questions posÃ©es dans le cas du massif du MÃ©zenc (Velay oriental, Sud-Est du Massif central, France). | C34: Pleistocene | D34: Pleistocene | E34: Q25546 | F34: 11945805t | H34: context | I34: context | J34: no | K34: 100 | L34: 110 | M34: Q312468;Q754897 | N34: epoch;series | O34: YES | P34: YES | U34: Nonlinear structural dynamics | V34: =COUNTIF(C34:C224, U34) -> 1
A35: 1131185 | B35: Les Â« riviÃ¨res de pierres Â» : une formation en marge des catÃ©gories classiques. Questions posÃ©es dans le cas du massif du MÃ©zenc (Velay oriental, Sud-Est du Massif central, France). | C35: Late Glacial | D35: Late Glacial Maximum | E35: Q2741484 | H35: context | I35: context | J35: no | K35: 75 | L35: 45 | M35: Q602963 | N35: glacial period | O35: YES | P35: YES | U35: Mistuned bladed disk | V35: =COUNTIF(C35:C225, U35) -> 1
A36: 1131185 | B36: Les Â« riviÃ¨res de pierres Â» : une formation en marge des catÃ©gories classiques. Questions posÃ©es dans le cas du massif du MÃ©zenc (Velay oriental, Sud-Est du Massif central, France). | C36: Eastern Velay | H36: none | I36: none | J36: no | K36: 0 | L36: 0 | O36: YES | P36: YES | U36: Geometrical nonlinearities | V36: =COUNTIF(C36:C226, U36) -> 1
A37: 1131185 | B37: Les Â« riviÃ¨res de pierres Â» : une formation en marge des catÃ©gories classiques. Questions posÃ©es dans le cas du massif du MÃ©zenc (Velay oriental, Sud-Est du Massif central, France). | C37: MÃ©zenc | D37: Mezenc | E37: Q128548547 | H37: context | I37: context | J37: no | K37: 100 | L37: 112 | M37: Q15069452 | N37: Natura 2000 site | O37: NO | P37: NO | Q37: keyword contains special character. The QID identified has no label defined. Potential QIDs: massif du Mézenc (Q3297689), Mont Mézenc Sud (Q34878583), Mount Mézenc (Q1267547), and Mont Mézenc Nord (Q34878573)… BnF IDs: massif du Mézenc (cb40616660p), Mont Mézenc and Nord(cb15199595z) | U37: Multiscale methods | V37: =COUNTIF(C37:C227, U37) -> 1
A38: 1131185 | B38: Les Â« riviÃ¨res de pierres Â» : une formation en marge des catÃ©gories classiques. Questions posÃ©es dans le cas du massif du MÃ©zenc (Velay oriental, Sud-Est du Massif central, France). | C38: Morphologie et processus pÃ©riglaciaires | H38: none | I38: none | J38: no | K38: 0 | L38: 0 | O38: YES | P38: YES | Q38: Contains special character | U38: Neural Networks | V38: =COUNTIF(C38:C228, U38) -> 6
A39: 1131185 | B39: Les Â« riviÃ¨res de pierres Â» : une formation en marge des catÃ©gories classiques. Questions posÃ©es dans le cas du massif du MÃ©zenc (Velay oriental, Sud-Est du Massif central, France). | C39: RiviÃ¨re de pierres | D39: RiviÃ¨re de pierre | E39: Q113579337 | H39: context | I39: context | J39: no | K39: 97.1 | L39: 109.3 | M39: Q55488 | N39: railway station | O39: NO | P39: NO | Q39: mismatched on the context | U39: High-dimensional approximation | V39: =COUNTIF(C39:C229, U39) -> 1
A40: 1131185 | B40: Les Â« riviÃ¨res de pierres Â» : une formation en marge des catÃ©gories classiques. Questions posÃ©es dans le cas du massif du MÃ©zenc (Velay oriental, Sud-Est du Massif central, France). | C40: Glacier rocheux | D40: rock glacier | E40: Q884736 | F40: 13507719g | G40: glacier > ice cover > body of water > region > geographical feature | H40: exact_label | I40: exact_label | J40: no | K40: 100 | L40: 50 | O40: YES | Q40: same as row 4 to 32 | U40: Computational homogenization | V40: =COUNTIF(C40:C230, U40) -> 1
A41: 1131185 | B41: Les Â« riviÃ¨res de pierres Â» : une formation en marge des catÃ©gories classiques. Questions posÃ©es dans le cas du massif du MÃ©zenc (Velay oriental, Sud-Est du Massif central, France). | C41: Glacier rocheux | D41: rock glacier | E41: Q884736 | F41: 13507719g | G41: glacier > ice cover > body of water > physico-geographical object > geographical feature | H41: exact_label | I41: exact_label | J41: no | K41: 100 | L41: 50 | O41: YES | Q41: same as row 4 to 32 | U41: Nonlinear homogenization | V41: =COUNTIF(C41:C231, U41) -> 1
A42: 1131185 | B42: Les Â« riviÃ¨res de pierres Â» : une formation en marge des catÃ©gories classiques. Questions posÃ©es dans le cas du massif du MÃ©zenc (Velay oriental, Sud-Est du Massif central, France). | C42: Glacier rocheux | D42: rock glacier | E42: Q884736 | F42: 13507719g | G42: glacier > ice cover > body of water > physico-geographical object > physical object | H42: exact_label | I42: exact_label | J42: no | K42: 100 | L42: 50 | O42: YES | Q42: same as row 4 to 32 | U42: Drillstring dynamics | V42: =COUNTIF(C42:C232, U42) -> 1
A43: 1131185 | B43: Les Â« riviÃ¨res de pierres Â» : une formation en marge des catÃ©gories classiques. Questions posÃ©es dans le cas du massif du MÃ©zenc (Velay oriental, Sud-Est du Massif central, France). | C43: Glacier rocheux | D43: rock glacier | E43: Q884736 | F43: 13507719g | G43: glacier > ice cover > body of water > habitat > region | H43: exact_label | I43: exact_label | J43: no | K43: 100 | L43: 50 | O43: YES | Q43: same as row 4 to 32 | U43: Horizontal drillstring | V43: =COUNTIF(C43:C233, U43) -> 1
A44: 1131185 | B44: Les Â« riviÃ¨res de pierres Â» : une formation en marge des catÃ©gories classiques. Questions posÃ©es dans le cas du massif du MÃ©zenc (Velay oriental, Sud-Est du Massif central, France). | C44: Glacier rocheux | D44: rock glacier | E44: Q884736 | F44: 13507719g | G44: glacier > ice cover > body of water > habitat > natural environment | H44: exact_label | I44: exact_label | J44: no | K44: 100 | L44: 50 | O44: YES | Q44: same as row 4 to 32; translated in French? | U44: Parametric probabilistic approach | V44: =COUNTIF(C44:C234, U44) -> 1
A45: 1131185 | B45: Les Â« riviÃ¨res de pierres Â» : une formation en marge des catÃ©gories classiques. Questions posÃ©es dans le cas du massif du MÃ©zenc (Velay oriental, Sud-Est du Massif central, France). | C45: Glacier rocheux | D45: rock glacier | E45: Q884736 | F45: 13507719g | G45: glacier > ice cover > glacial landform > landform > geomorphological unit | H45: exact_label | I45: exact_label | J45: no | K45: 100 | L45: 50 | O45: YES | Q45: same as row 4 to 32; translated in French? | U45: Robust optimization | V45: =COUNTIF(C45:C235, U45) -> 6
A46: 1131185 | B46: Les Â« riviÃ¨res de pierres Â» : une formation en marge des catÃ©gories classiques. Questions posÃ©es dans le cas du massif du MÃ©zenc (Velay oriental, Sud-Est du Massif central, France). | C46: Glacier rocheux | D46: rock glacier | E46: Q884736 | F46: 13507719g | G46: glacier > ice cover > glacial landform > landform > geographical feature | H46: exact_label | I46: exact_label | J46: no | K46: 100 | L46: 50 | O46: YES | Q46: same as row 4 to 32; translated in French? | U46: Optimal sensor placement | V46: =COUNTIF(C46:C236, U46) -> 1
A47: 1131185 | B47: Les Â« riviÃ¨res de pierres Â» : une formation en marge des catÃ©gories classiques. Questions posÃ©es dans le cas du massif du MÃ©zenc (Velay oriental, Sud-Est du Massif central, France). | C47: Glacier rocheux | D47: rock glacier | E47: Q884736 | F47: 13507719g | G47: glacier > ice cover > glacial landform > landform > geographic location | H47: exact_label | I47: exact_label | J47: no | K47: 100 | L47: 50 | O47: YES | Q47: same as row 4 to 32; translated in French? | U47: Model updating | V47: =COUNTIF(C47:C237, U47) -> 1
...

Sheet Sheet1
A1: {=_xlfn.UNIQUE(Wikidata_upec_chemical_20!A:A)} -> docid | B1: {=_xlfn.UNIQUE(Wikidata_upec_chemical_20!C:C)} -> keyword | D1: QID | E1: BNF_id | G1: Total articles | H1: =COUNTA($A$2:$A$21) -> 20
A2: 1006198 | B2: Mixed convection | C2: =VLOOKUP(B2,Wikidata_upec_chemical_20!$C:$O,13,FALSE) -> ok | D2: =IF(VLOOKUP(B2,Wikidata_upec_chemical_20!$C:$O,3,FALSE)<>0,"yes","no") -> no | E2: =IF(VLOOKUP(B2,Wikidata_upec_chemical_20!$C:$O,4,FALSE)<>0,"yes","no") -> no | G2: Total | H2: =COUNTA($B$2:$B$96) -> 95
A3: 1025697 | B3: Poiseuille-Rayleigh-BÃ©nard flow | C3: =VLOOKUP(B3,Wikidata_upec_chemical_20!$C:$O,13,FALSE) -> ok | D3: =IF(VLOOKUP(B3,Wikidata_upec_chemical_20!$C:$O,3,FALSE)<>0,"yes","no") -> no | E3: =IF(VLOOKUP(B3,Wikidata_upec_chemical_20!$C:$O,4,FALSE)<>0,"yes","no") -> no | G3: ok | H3: =COUNTIF($C$2:$C$96,G3) -> 73 | I3: =H3/H2 -> 0.76842105
A4: 1060481 | B4: Convective instability | C4: =VLOOKUP(B4,Wikidata_upec_chemical_20!$C:$O,13,FALSE) -> ok | D4: =IF(VLOOKUP(B4,Wikidata_upec_chemical_20!$C:$O,3,FALSE)<>0,"yes","no") -> yes | E4: =IF(VLOOKUP(B4,Wikidata_upec_chemical_20!$C:$O,4,FALSE)<>0,"yes","no") -> no | G4: Wrong | H4: =COUNTIF($C$2:$C$96,G4) -> 22 | I4: =1-I3 -> 0.23157895
A5: 1064801 | B5: Rectangular channel | C5: =VLOOKUP(B5,Wikidata_upec_chemical_20!$C:$O,13,FALSE) -> ok | D5: =IF(VLOOKUP(B5,Wikidata_upec_chemical_20!$C:$O,3,FALSE)<>0,"yes","no") -> no | E5: =IF(VLOOKUP(B5,Wikidata_upec_chemical_20!$C:$O,4,FALSE)<>0,"yes","no") -> no | G5: QID | H5: =COUNTIF($D$2:$D$96,"yes") -> 44 | I5: =H5/H2 -> 0.46315789
A6: 1067996 | B6: Harmonic inlet excitation | C6: =VLOOKUP(B6,Wikidata_upec_chemical_20!$C:$O,13,FALSE) -> ok | D6: =IF(VLOOKUP(B6,Wikidata_upec_chemical_20!$C:$O,3,FALSE)<>0,"yes","no") -> no | E6: =IF(VLOOKUP(B6,Wikidata_upec_chemical_20!$C:$O,4,FALSE)<>0,"yes","no") -> no | G6: BNF_ID | H6: =COUNTIF($E$2:$E$96,"yes") -> 5 | I6: =H6/H2 -> 0.052631579
A7: 1078652 | B7: CVD | C7: =VLOOKUP(B7,Wikidata_upec_chemical_20!$C:$O,13,FALSE) -> ok | D7: =IF(VLOOKUP(B7,Wikidata_upec_chemical_20!$C:$O,3,FALSE)<>0,"yes","no") -> no | E7: =IF(VLOOKUP(B7,Wikidata_upec_chemical_20!$C:$O,4,FALSE)<>0,"yes","no") -> no
A8: 1078896 | B8: 3D numerical simulations | C8: =VLOOKUP(B8,Wikidata_upec_chemical_20!$C:$O,13,FALSE) -> ok | D8: =IF(VLOOKUP(B8,Wikidata_upec_chemical_20!$C:$O,3,FALSE)<>0,"yes","no") -> no | E8: =IF(VLOOKUP(B8,Wikidata_upec_chemical_20!$C:$O,4,FALSE)<>0,"yes","no") -> no
A9: 1083001 | B9: Design of experiments | C9: =VLOOKUP(B9,Wikidata_upec_chemical_20!$C:$O,13,FALSE) -> Ok | D9: =IF(VLOOKUP(B9,Wikidata_upec_chemical_20!$C:$O,3,FALSE)<>0,"yes","no") -> yes | E9: =IF(VLOOKUP(B9,Wikidata_upec_chemical_20!$C:$O,4,FALSE)<>0,"yes","no") -> no
A10: 1083004 | B10: Corrosion | C10: =VLOOKUP(B10,Wikidata_upec_chemical_20!$C:$O,13,FALSE) -> Wrong | D10: =IF(VLOOKUP(B10,Wikidata_upec_chemical_20!$C:$O,3,FALSE)<>0,"yes","no") -> yes | E10: =IF(VLOOKUP(B10,Wikidata_upec_chemical_20!$C:$O,4,FALSE)<>0,"yes","no") -> no
A11: 1083007 | B11: Ni-MH batteries | C11: =VLOOKUP(B11,Wikidata_upec_chemical_20!$C:$O,13,FALSE) -> ok | D11: =IF(VLOOKUP(B11,Wikidata_upec_chemical_20!$C:$O,3,FALSE)<>0,"yes","no") -> no | E11: =IF(VLOOKUP(B11,Wikidata_upec_chemical_20!$C:$O,4,FALSE)<>0,"yes","no") -> no
A12: 1083014 | B12: Raman micro spectroscopy | C12: =VLOOKUP(B12,Wikidata_upec_chemical_20!$C:$O,13,FALSE) -> ok | D12: =IF(VLOOKUP(B12,Wikidata_upec_chemical_20!$C:$O,3,FALSE)<>0,"yes","no") -> no | E12: =IF(VLOOKUP(B12,Wikidata_upec_chemical_20!$C:$O,4,FALSE)<>0,"yes","no") -> no
A13: 1083157 | B13: TEM | C13: =VLOOKUP(B13,Wikidata_upec_chemical_20!$C:$O,13,FALSE) -> Ok | D13: =IF(VLOOKUP(B13,Wikidata_upec_chemical_20!$C:$O,3,FALSE)<>0,"yes","no") -> yes | E13: =IF(VLOOKUP(B13,Wikidata_upec_chemical_20!$C:$O,4,FALSE)<>0,"yes","no") -> yes
A14: 1083160 | B14: Combination of techniques | C14: =VLOOKUP(B14,Wikidata_upec_chemical_20!$C:$O,13,FALSE) -> ok | D14: =IF(VLOOKUP(B14,Wikidata_upec_chemical_20!$C:$O,3,FALSE)<>0,"yes","no") -> no | E14: =IF(VLOOKUP(B14,Wikidata_upec_chemical_20!$C:$O,4,FALSE)<>0,"yes","no") -> no
A15: 1084520 | B15: 20902069 | C15: =VLOOKUP(B15,Wikidata_upec_chemical_20!$C:$O,13,FALSE) -> ok | D15: =IF(VLOOKUP(B15,Wikidata_upec_chemical_20!$C:$O,3,FALSE)<>0,"yes","no") -> no | E15: =IF(VLOOKUP(B15,Wikidata_upec_chemical_20!$C:$O,4,FALSE)<>0,"yes","no") -> no
A16: 1084657 | B16: Nsfc | C16: =VLOOKUP(B16,Wikidata_upec_chemical_20!$C:$O,13,FALSE) -> ok | D16: =IF(VLOOKUP(B16,Wikidata_upec_chemical_20!$C:$O,3,FALSE)<>0,"yes","no") -> no | E16: =IF(VLOOKUP(B16,Wikidata_upec_chemical_20!$C:$O,4,FALSE)<>0,"yes","no") -> no
A17: 1084678 | B17: National natural science foundation of china | C17: =VLOOKUP(B17,Wikidata_upec_chemical_20!$C:$O,13,FALSE) -> ok | D17: =IF(VLOOKUP(B17,Wikidata_upec_chemical_20!$C:$O,3,FALSE)<>0,"yes","no") -> yes | E17: =IF(VLOOKUP(B17,Wikidata_upec_chemical_20!$C:$O,4,FALSE)<>0,"yes","no") -> no
A18: 1086746 | B18: 21074094 | C18: =VLOOKUP(B18,Wikidata_upec_chemical_20!$C:$O,13,FALSE) -> ok | D18: =IF(VLOOKUP(B18,Wikidata_upec_chemical_20!$C:$O,3,FALSE)<>0,"yes","no") -> no | E18: =IF(VLOOKUP(B18,Wikidata_upec_chemical_20!$C:$O,4,FALSE)<>0,"yes","no") -> no
A19: 1086752 | B19: 51173134 | C19: =VLOOKUP(B19,Wikidata_upec_chemical_20!$C:$O,13,FALSE) -> ok | D19: =IF(VLOOKUP(B19,Wikidata_upec_chemical_20!$C:$O,3,FALSE)<>0,"yes","no") -> no | E19: =IF(VLOOKUP(B19,Wikidata_upec_chemical_20!$C:$O,4,FALSE)<>0,"yes","no") -> no
A20: 1087358 | B20: Potential curves | C20: =VLOOKUP(B20,Wikidata_upec_chemical_20!$C:$O,13,FALSE) -> ok | D20: =IF(VLOOKUP(B20,Wikidata_upec_chemical_20!$C:$O,3,FALSE)<>0,"yes","no") -> no | E20: =IF(VLOOKUP(B20,Wikidata_upec_chemical_20!$C:$O,4,FALSE)<>0,"yes","no") -> no
A21: 1088019 | B21: Long range interactions | C21: =VLOOKUP(B21,Wikidata_upec_chemical_20!$C:$O,13,FALSE) -> ok | D21: =IF(VLOOKUP(B21,Wikidata_upec_chemical_20!$C:$O,3,FALSE)<>0,"yes","no") -> no | E21: =IF(VLOOKUP(B21,Wikidata_upec_chemical_20!$C:$O,4,FALSE)<>0,"yes","no") -> no
A22: 0 | B22: Ab-initio calculations | C22: =VLOOKUP(B22,Wikidata_upec_chemical_20!$C:$O,13,FALSE) -> ok | D22: =IF(VLOOKUP(B22,Wikidata_upec_chemical_20!$C:$O,3,FALSE)<>0,"yes","no") -> no | E22: =IF(VLOOKUP(B22,Wikidata_upec_chemical_20!$C:$O,4,FALSE)<>0,"yes","no") -> no
B23: Hydrogen halides | C23: =VLOOKUP(B23,Wikidata_upec_chemical_20!$C:$O,13,FALSE) -> ok | D23: =IF(VLOOKUP(B23,Wikidata_upec_chemical_20!$C:$O,3,FALSE)<>0,"yes","no") -> yes | E23: =IF(VLOOKUP(B23,Wikidata_upec_chemical_20!$C:$O,4,FALSE)<>0,"yes","no") -> no
B24: 5210 PLANETARY SCIENCES ASTROBIOLOGY Planetary atmospheres | C24: =VLOOKUP(B24,Wikidata_upec_chemical_20!$C:$O,13,FALSE) -> ok | D24: =IF(VLOOKUP(B24,Wikidata_upec_chemical_20!$C:$O,3,FALSE)<>0,"yes","no") -> no | E24: =IF(VLOOKUP(B24,Wikidata_upec_chemical_20!$C:$O,4,FALSE)<>0,"yes","no") -> no
B25: Clouds | C25: =VLOOKUP(B25,Wikidata_upec_chemical_20!$C:$O,13,FALSE) -> Wrong | D25: =IF(VLOOKUP(B25,Wikidata_upec_chemical_20!$C:$O,3,FALSE)<>0,"yes","no") -> yes | E25: =IF(VLOOKUP(B25,Wikidata_upec_chemical_20!$C:$O,4,FALSE)<>0,"yes","no") -> no
B26: And hazes | C26: =VLOOKUP(B26,Wikidata_upec_chemical_20!$C:$O,13,FALSE) -> ok | D26: =IF(VLOOKUP(B26,Wikidata_upec_chemical_20!$C:$O,3,FALSE)<>0,"yes","no") -> no | E26: =IF(VLOOKUP(B26,Wikidata_upec_chemical_20!$C:$O,4,FALSE)<>0,"yes","no") -> no
B27: 5405 PLANETARY SCIENCES SOLID SURFACE PLANETS Atmospheres | C27: =VLOOKUP(B27,Wikidata_upec_chemical_20!$C:$O,13,FALSE) -> ok | D27: =IF(VLOOKUP(B27,Wikidata_upec_chemical_20!$C:$O,3,FALSE)<>0,"yes","no") -> no | E27: =IF(VLOOKUP(B27,Wikidata_upec_chemical_20!$C:$O,4,FALSE)<>0,"yes","no") -> no
B28: 0305 ATMOSPHERIC COMPOSITION AND STRUCTURE Aerosols and particles | C28: =VLOOKUP(B28,Wikidata_upec_chemical_20!$C:$O,13,FALSE) -> ok | D28: =IF(VLOOKUP(B28,Wikidata_upec_chemical_20!$C:$O,3,FALSE)<>0,"yes","no") -> no | E28: =IF(VLOOKUP(B28,Wikidata_upec_chemical_20!$C:$O,4,FALSE)<>0,"yes","no") -> no
B29: Parallel Charging | C29: =VLOOKUP(B29,Wikidata_upec_chemical_20!$C:$O,13,FALSE) -> ok | D29: =IF(VLOOKUP(B29,Wikidata_upec_chemical_20!$C:$O,3,FALSE)<>0,"yes","no") -> no | E29: =IF(VLOOKUP(B29,Wikidata_upec_chemical_20!$C:$O,4,FALSE)<>0,"yes","no") -> no
